Workbook
Name Фундамент: Итог!$48:$56

Sheet Ввод информации
A1: 1. Введите общую длину забора | D1: да
A2: 128
A3: 2. Введите высоту забора
A4: 2
A5: 3. Выберите материал
A6: Профнастил | B6: Штакет | C6: ШТ Шахматка
A7: TRUE | B7: FALSE | C7: FALSE
A8: 4. Выберете ширину зазора между штакетом
A9: 0.04
A10: Профлист RAL 0.45мм профиль С8
A12: 6. Выберите цвет RAL финишного покрытия
A13: RAL 8017
A14: 7. Выберите способ крепления
A15: Саморез кровельный в цвет
A16: 8. Выберите наличие ворот и калиток и количество
A17: Калитка | B17: TRUE | C17: FALSE
A18: Ворота откатные | B18: TRUE | C18: FALSE
A19: Ворота распашные | B19: FALSE | C19: FALSE
A20: 9. Выберите столбы
A21: Столб заборный 60х60х2мм | C21: TRUE
A22: Столб заборный 73мм НКТ | C22: FALSE
A23: Столб заборный 60х40х2мм | C23: FALSE
A24: Столб заборный 80х80х2мм | C24: FALSE
A25: 10. Количество рядов лаг
A26: 2 ряда | C26: TRUE
A27: 3 ряда | C27: FALSE
A28: 11. Расстояние до объекта
A29: 60
A30: 12. Расcчитать фундамент (Поставьте галочку и введите параметры ниже): | C30: TRUE
A31: Длина (м.п.) | C31: 64
A32: Ширина (метров) | C32: 0.25
A33: Высота (метров) | C33: 0.6
A34: Адрес объекта
A35: КП Заповедник парк Совята уч 81
A36: Контактное лицо и телефон
A37: Борис Борисович +7-912-297-11-79

Sheet Параметры для расчета
A1: Расчет показателей | C1: кол-во | E1: цена
A2: Количество столбов под забор | C2: =('Ввод информации'!A2-(D43*1)-(D44*4)-(D45*4))/3 -> 41 | D2: 41
A3: Цена установки столбов | E3: =IF('Ввод информации'!A2<30,500,IF('Ввод информации'!A2<50,450,400)) -> 400
A4: Монтаж забора | D4: ='Ввод информации'!A2-(D5*4)-(D6*4)-D7 -> 123 | E4: =IF('Ввод информации'!A2<30,1000,IF('Ввод информации'!A2<50,900,IF('Ввод информации'!A2<100,800,700))) -> 700 | F4: =E4+150 -> 850
A5: Монтаж ворот откатных | D5: =IF('Ввод информации'!B18,1,0)+IF('Ввод информации'!C18,1,0) -> 1 | E5: =Цены!C23 -> 32000
A6: Монтаж ворот распашных | D6: =IF('Ввод информации'!B19,1,0)+IF('Ввод информации'!C19,1,0) -> 0 | E6: =Цены!C24 -> 7500
A7: Монтаж калитки | D7: =IF('Ввод информации'!B17,1,0)+IF('Ввод информации'!C17,1,0) -> 1 | E7: =Цены!C25 -> 4500
A8: Покраска металлоконструкции | D8: =(D50*3)+(D2*2)+(D43*7)+(D44*70)+(D45*40) -> 405 | E8: =IF('Ввод информации'!A2<30,50,IF('Ввод информации'!A2<50,30,25)) -> 25
A9: Монтажные работы по заливке фундамента | C9: =IF(C64>8,"м3", IF(C64<8,"м.п.")) -> м3 | D9: =IF(C64>8,C64, IF(C64<8,'Ввод информации'!C31)) -> 9.6 | E9: =IF(C64>8,4900, IF(C64<8,1900)) -> 4900
A11: Расчет финишного материала
A12: Профлист
A13: =IF('Ввод информации'!A7=TRUE,'Ввод информации'!A10, IF('Ввод информации'!A7=FALSE," ", IF('Ввод информации'!B7=TRUE," ",IF('Ввод информации'!C7=TRUE," ", )))) -> Профлист RAL 0.45мм профиль С8 | C13: =('Ввод информации'!A2/1.15)+'Параметры для расчета'!D43+'Параметры для расчета'!D44+'Параметры для расчета'!D45 -> 113.30435 | D13: 114 | E13: =IFERROR(VLOOKUP(A13,Цены!A44:B54,2,0),0)*'Ввод информации'!A4*1.22 -> 1134.6
A15: Штакет
A16: ='Ввод информации'!A10 -> Профлист RAL 0.45мм профиль С8 | C16: ='Ввод информации'!A2/(C17+C18) -> 3200 | D16: 3200 | E16: =IFERROR(VLOOKUP(A16,Цены!A55:B89,2,0),0)*'Ввод информации'!A4 -> 0
A17: Ширина | C17: =IFERROR(VLOOKUP(A16,A85:B109,2,0),0) -> 0
A18: Зазор | C18: ='Ввод информации'!A9 -> 0.04
A19: 0.01
A20: 0.02
A21: 0.03
A22: 0.04
A23: 0.05
A24: 0.06
A25: 0.07
A26: 0.08
A28: Шахматка | C28: =D16*2 -> 6400 | D28: 6400 | E28: =E16*2 -> 0
A30: Саморез кровельный в цвет | E30: 3.5
A31: Саморез с пресс-шайбой | E31: 1.5
A32: саморез | E32: =VLOOKUP('Ввод информации'!A15,A30:E31,5) -> 3.5
A33: Профнастил | C33: ='Ввод информации'!A2*'Ввод информации'!A4*6 -> 1536 | D33: =ROUNDUP(C33/250,0)*250 -> 1750
A34: Штакетник | D34: =D16*4 -> 12800
A35: Наибольшее значение | D35: =LARGE(D33:D34,1) -> 12800
A37: Столб заборный 60х60х2мм | C37: =IF('Ввод информации'!C21,1,0) -> 1 | D37: =IF(C37,1,0) -> 1
A38: Столб заборный 73мм НКТ | C38: =IF('Ввод информации'!C22,1,0) -> 0 | D38: =IF(C38,2,0) -> 0
A39: Столб заборный 60х40х2мм | C39: =IF('Ввод информации'!C23,1,0) -> 0 | D39: =IF(C39,3,0) -> 0
A40: Столб заборный 80х80х2мм | C40: =IF('Ввод информации'!C24,1,0) -> 0 | D40: =IF(C40,4,0) -> 0
A41: =IF('Ввод информации'!C21,'Ввод информации'!A21,IF('Ввод информации'!C22,'Ввод информации'!A22,IF('Ввод информации'!C23,'Ввод информации'!A23,IF('Ввод информации'!C24,'Ввод информации'!A24)))) -> Столб заборный 60х60х2мм | D41: =IF('Ввод информации'!C21,1,IF('Ввод информации'!C22,2,IF('Ввод информации'!C23,3,IF('Ввод информации'!C24,4)))) -> 1 | E41: =+CHOOSE(D41,Цены!C6,Цены!C7,Цены!C8,Цены!C9) -> 944
A43: Калитка | D43: =IF('Ввод информации'!B17,1,0)+IF('Ввод информации'!C17,1,0) -> 1
A44: Ворота откатные | D44: =IF('Ввод информации'!B18,1,0)+IF('Ввод информации'!C18,1,0) -> 1
A45: Ворота распашные | D45: =IF('Ввод информации'!B19,1,0)+IF('Ввод информации'!C19,1,0) -> 0 | F45: Каркас ворот распашных с доборными элементами стандартный размер
A46: Количество столбов под ворота и калитки | D46: =(D43*2)+(D44*2)+(D45*2) -> 4 | E46: 1275
...

Sheet Итог
E1: 1
E2: Общество с ограниченной ответственностью
E3: "Дача 2000"
E4: 624091, Свердловская обл., г. Екатеринбург, ул. 8 Марта, д. 207, оф. 27.
E5: Калькуляция №1
E6: 1
E7: 1
B8: Наименование объекта: Монтаж забора | E8: 1 | G8: ='Ввод информации'!A35 -> КП Заповедник парк Совята уч 81
B9: ='Ввод информации'!A37 -> Борис Борисович +7-912-297-11-79 | E9: 1 | G9: Забор из штакетника в шахматном порядке с шагом 4см.
E10: 1 | H10: Сметная стоимость: | J10: =J11+J12 -> 806636.82
E11: 1 | H11: Стоимость работы: | J11: =I58 -> 240015
E12: 1 | H12: Стоимость материалов: | J12: =J58 -> 566621.82
A13: № п/п | B13: Наименование работ и затрат | C13: Ед. изм. | D13: Коэфф | E13: 1 | F13: Стоимость единицы, руб | H13: Общая стоимость, руб
E14: Кол-во | F14: в т.ч.: | H14: Всего | I14: в т.ч.:
E15: 1 | F15: Стоимость работ | G15: Стоимость материала | I15: Стоимость работ | J15: Стоимость материала
A16: 1 | B16: Монтаж столбов на глубину бурения. Выставление по уровню в 2 осях, с заливкой бетоном. Расстояние по осям не более 3х метров. | C16: шт. | D16: 1 | E16: 25 | F16: ='Параметры для расчета'!E3 -> 400 | H16: =E16*F16 -> 10000 | I16: =H16 -> 10000
A17: 2 | B17: Бурение отверстий в грунте глубиной 1500мм | C17: шт | D17: 1 | E17: 25 | F17: ='Параметры для расчета'!E3 -> 400 | H17: =E17*F17 -> 10000 | I17: =H17 -> 10000
A18: 3 | B18: Монтаж забора | C18: м.п. | D18: 1 | E18: 113 | F18: 950 | H18: =E18*F18 -> 107350 | I18: =H18 -> 107350
A19: 4 | B19: ='Параметры для расчета'!A5 -> Монтаж ворот откатных | C19: шт | D19: 1 | E19: ='Параметры для расчета'!D5 -> 1 | F19: ='Параметры для расчета'!E5 -> 32000 | H19: =E19*F19 -> 32000 | I19: =H19 -> 32000
A20: 5 | B20: ='Параметры для расчета'!A6 -> Монтаж ворот распашных | C20: шт | D20: 1 | E20: ='Параметры для расчета'!D6 -> 0 | F20: ='Параметры для расчета'!E6 -> 7500 | H20: =E20*F20 -> 0 | I20: =H20 -> 0
A21: 5 | B21: ='Параметры для расчета'!A7 -> Монтаж калитки | C21: шт | D21: 1 | E21: ='Параметры для расчета'!D7 -> 1 | F21: ='Параметры для расчета'!E7 -> 4500 | H21: =E21*F21 -> 4500 | I21: =H21 -> 4500
A22: 6 | B22: ='Параметры для расчета'!A8 -> Покраска металлоконструкции | C22: м.п. | D22: 1 | E22: 397 | F22: ='Параметры для расчета'!E8 -> 25 | H22: =E22*F22 -> 9925 | I22: =H22 -> 9925
A23: 7 | B23: =IF('Ввод информации'!C30=TRUE,'Параметры для расчета'!A9, IF('Ввод информации'!C30=FALSE,)) -> Монтажные работы по заливке фундамента | C23: =IF('Ввод информации'!C30=TRUE,'Параметры для расчета'!C9, IF('Ввод информации'!C30=FALSE,)) -> м3 | D23: =IF('Ввод информации'!C30=TRUE,1, IF('Ввод информации'!C30=FALSE,0)) -> 1 | E23: =IF('Ввод информации'!C30=TRUE,'Параметры для расчета'!D9, IF('Ввод информации'!C30=FALSE,0)) -> 9.6 | F23: 6900 | H23: =E23*F23 -> 66240 | I23: =H23 -> 66240
A24: 8 | B24: =IF(H24=0," ",IF(H24>0,'Ввод информации'!A10)) -> Профлист RAL 0.45мм профиль С8 | C24: шт | D24: 1 | E24: 85 | G24: 1469 | H24: =E24*G24 -> 124865 | J24: =H24 -> 124865
A25: 9 | B25: ='Ввод информации'!A15 -> Саморез кровельный в цвет | C25: шт | D25: 1 | E25: 1250 | G25: ='Параметры для расчета'!E32 -> 3.5 | H25: =E25*G25 -> 4375 | J25: =H25 -> 4375
A26: 10 | B26: Штакет 131мм под дерево | C26: шт | D26: 1 | E26: 285 | G26: 368 | H26: =E26*G26 -> 104880 | J26: =H26 -> 104880
A27: 11 | B27: Саморез с пресшайбой | C27: шт | D27: 1 | E27: 1500 | G27: 1.5 | H27: =E27*G27 -> 2250 | J27: =H27 -> 2250
A28: 12 | B28: ='Параметры для расчета'!A41 -> Столб заборный 60х60х2мм | C28: шт | D28: 1 | E28: 14 | G28: ='Параметры для расчета'!E41 -> 944 | H28: =E28*G28 -> 13216 | J28: =H28 -> 13216
A29: 3 | B29: Столб под ворота и калитки 80х80х3000 стенка 2мм | C29: шт | D29: 1 | E29: 13 | G29: ='Параметры для расчета'!E46 -> 1275 | H29: =E29*G29 -> 16575 | J29: =H29 -> 16575
A30: 14 | B30: Электроды сварочные Ок-46 3мм | C30: шт | D30: 1 | E30: ='Параметры для расчета'!D48 -> 2 | G30: ='Параметры для расчета'!E48 -> 2600 | H30: =E30*G30 -> 5200 | J30: =H30 -> 5200
A31: 15 | B31: Краска грунт эмаль по ржавчине 3в1 | C31: шт | D31: 1 | E31: ='Параметры для расчета'!D49 -> 5 | G31: ='Параметры для расчета'!E49 -> 2200 | H31: =E31*G31 -> 11000 | J31: =H31 -> 11000
A32: 16 | B32: Лага заборная 40х20х3000мм стенка 1,5мм | C32: шт | D32: 1 | E32: ='Параметры для расчета'!D50 -> 82 | G32: ='Параметры для расчета'!E50 -> 362 | H32: =E32*G32 -> 29684 | J32: =H32 -> 29684
A33: 17 | B33: Каркас ворот откатных с доборными элементами и швеллером стандартный размер | C33: шт | D33: 1 | E33: ='Параметры для расчета'!D44 -> 1 | G33: =Цены!C2 -> 45500 | H33: =E33*G33 -> 45500 | J33: =H33 -> 45500
A34: 17 | B34: Каркас ворот распашных с доборными элементами стандартный размер | C34: шт | D34: 1 | E34: ='Параметры для расчета'!D45 -> 0 | G34: =Цены!C3 -> 19500 | H34: =E34*G34 -> 0 | J34: =H34 -> 0
A35: 18 | B35: Каркас калитки стандартный размер | C35: шт | D35: 1 | E35: ='Параметры для расчета'!D43 -> 1 | G35: =Цены!C4 -> 9500 | H35: =E35*G35 -> 9500 | J35: =H35 -> 9500
A36: 19 | B36: Валик полиакрил в комплекте с бюгелем | C36: шт | D36: 1 | E36: ='Параметры для расчета'!D58 -> 6 | G36: ='Параметры для расчета'!E58 -> 250 | H36: =E36*G36 -> 1500 | J36: =H36 -> 1500
A37: 20 | B37: Заглушки для столбов в подарок | C37: шт | D37: 1 | E37: =E28+E29 -> 27 | G37: 0 | H37: =E37*G37 -> 0 | J37: =H37 -> 0
A38: 21 | B38: Замок в калитку с ручкой (цилиндр и механизм Zn) | C38: шт | D38: 1 | E38: ='Параметры для расчета'!D43 -> 1 | G38: =Цены!C1 -> 2250 | H38: =E38*G38 -> 2250 | J38: =H38 -> 2250
A39: 22 | B39: Диски отрезные 125х1,2 | C39: шт | D39: 1 | E39: ='Параметры для расчета'!D57 -> 13 | G39: ='Параметры для расчета'!E57 -> 35 | H39: =G39*E39 -> 455 | J39: =G39 -> 35
A40: 23 | B40: Цинк холодный в балончике для обработки швов | C40: шт | D40: 1 | E40: ='Параметры для расчета'!D59 -> 2 | G40: ='Параметры для расчета'!E59 -> 450 | H40: =G40*E40 -> 900 | J40: =G40 -> 450
...

Sheet Цены
A1: Замок в калитку | C1: 2250
A2: Ворота откатные со швеллером балкой и роликами | C2: 45500
A3: Ворота распашные стандарт | C3: 19500
A4: Калитка стандарт | C4: 9500
A6: Столб 60х60х2мм | C6: 944
A7: Столб 73мм НКТ | C7: 1042
A8: Столб 60х40х2мм | C8: 772
A9: Столб 80х80х2мм | C9: 1273
A11: Профнастил, цена за м2 | C11: 344
A14: Цемент | C14: 450
A15: Щебень | C15: 160
A16: Отсев | C16: 160
... A25: Монтаж калитки | C25: 4500
A27: Столбы: | C27: цена м.п.
A28: Столб (профильная труба) 60х60 станка 2мм под покраску
A29: Столб НКТ диаметр 73мм толщина стенки 5,5мм под покраску
A30: Столб НКТ диаметр 60мм толщина стенки 5мм под покраску
A31: Столб (профильная труба) 60х40 станка 2мм под покраску
A32: Столб (профильная труба) 80х80 станка 2мм под покраску
A33: Столб (профильная труба) 100х100 станка 2мм под покраску
A34: Столб каменное дерево EcoGreen 95х95х3000
A35: Столб каменное дерево EcoBurn 100х100х3000
A36: Столб (профильная труба) 60х40 станка 1,5мм ППЛД
A37: Столб (профильная труба) 60х60 станка 1,5мм ППЛД
A38: Столб (профильная труба) 62х55 станка 1,5мм ППЛД
A39: Столб (профильная труба) 60х60 станка 2мм ППЛД
A41: Лага заборная 40х20х3000 под покраску
A43: Финишный материал: | C43: цена за ед. измерения
A44: Профлист оцинкованный 0.4мм профиль С8 | B44: 348 | C44: 342
A45: Профлист оцинкованный 0.45мм профиль С8 | B45: 384 | C45: 377
A46: Профлист оцинкованный 0.5мм профиль С8 | B46: 400 | C46: 394
A47: Профлист RAL 0.4мм профиль С8 | B47: 434 | C47: 430
A48: Профлист RAL 0.45мм профиль С8 | B48: 465 | C48: 460
A49: Профлист RAL 0.5мм профиль С8 | B49: 486 | C49: 486
A50: Профлист RAL 0.4мм 2х сторонний профиль С8
A51: Профлист RAL 0.45мм 2х сторонний профиль С8 | B51: 505 | C51: 505
A52: Профлист RAL 0.5мм 2х сторонний профиль С8 | B52: 526 | C52: 526
A53: Профлист двухсторонний 0.45мм профиль С8 | B53: 505 | C53: 625
A54: Профлист двухсторонний под дерево 0.45мм профиль С8 | B54: 674 | C54: 739
A55: Штакет оцинкованный 75 | B55: 42 | C55: 42
...
